Workbook
Name DomainFilterList: _xlfn.ANCHORARRAY('Chart Data'!$A$2)
Name MemberFilterList: _xlfn.ANCHORARRAY('Chart Data'!$M$2)

Sheet Team Skill
A1: Domain | B1: Skill | C1: Toàn | D1: Long | E1: Tuấn | F1: Duy | G1: Sang | H1: Bảo | I1: Thông | J1: Khánh | K1: NV.A | L1: Owner | M1: Backup | N1: SME
A2: Virtualization | B2: VMware ESXi | C2: L2 | D2: L2 | E2: L2 | F2: L2 | G2: L2 | H2: L2 | I2: L2 | J2: L2
A3: Virtualization | B3: VMware vCenter | C3: L2 | D3: L2 | E3: L2 | F3: L2 | G3: L2 | H3: L2 | I3: L2 | J3: L2
A4: Virtualization | B4: VMware vSAN | C4: L2 | D4: L1 | E4: L1 | F4: L2 | G4: L2 | H4: L1 | I4: L0 | J4: L1
A5: Virtualization | B5: VMware NSX | C5: L0 | D5: L1 | E5: L1 | F5: L1 | G5: L1 | H5: L1 | I5: L0 | J5: L0
A6: Virtualization | B6: VMware Horizon | C6: L0 | D6: L0 | E6: L2 | F6: L2 | G6: L2 | H6: L1 | I6: L0 | J6: L0
A7: Virtualization | B7: Proxmox VE | C7: L1 | D7: L0 | E7: L1 | F7: L2 | G7: L2 | H7: L2 | I7: L1 | J7: L2
A8: Virtualization | B8: Hyper-V | C8: L2 | D8: L1 | E8: L2 | F8: L2 | G8: L2 | H8: L2 | I8: L2 | J8: L1
A9: Virtualization | B9: XCP-ng | C9: L2 | D9: L0 | E9: L0 | F9: L0 | G9: L2 | H9: L0 | I9: L0 | J9: L0
A10: Virtualization | B10: HPE | C10: L1 | D10: L0 | E10: L1 | F10: L0 | G10: L0 | H10: L0 | I10: L0 | J10: L0
A11: Virtualization | B11: VergeIO | C11: L0 | D11: L0 | E11: L0 | F11: L2 | G11: L2 | H11: L0 | I11: L0 | J11: L0
A12: Virtualization | B12: Nutanix | C12: L0 | D12: L0 | E12: L0 | F12: L1 | G12: L1 | H12: L0 | I12: L0 | J12: L0
A13: Virtualization | B13: CloudStack | C13: L0 | D13: L0 | E13: L0 | F13: L1 | G13: L2 | H13: L0 | I13: L0 | J13: L0
... A71: Security | B71: Trend Micro | C71: L1 | D71: L1 | E71: L2 | F71: L2 | G71: L1 | H71: L2 | I71: L0 | J71: L0
A72: Security | B72: Defender | C72: L0 | D72: L0 | E72: L0 | G72: L0 | H72: L0 | I72: L0 | J72: L0
A73: Security | B73: LDAP | C73: L1 | D73: L1 | E73: L2 | F73: L2 | G73: L2 | H73: L2 | I73: L2 | J73: L0
A74: Security | B74: IDS/IPS | C74: L1 | D74: L2 | E74: L2 | F74: L1 | G74: L2 | H74: L1 | I74: L1 | J74: L1
A75: Security | B75: NAC | C75: L0 | D75: L1 | E75: L1 | F75: L2 | G75: L2 | H75: L1 | I75: L1 | J75: L0
A76: Security | B76: PKI | C76: L0 | D76: L1 | E76: L1 | F76: L0 | G76: L2 | H76: L0 | I76: L0 | J76: L0
A77: Security | B77: MFA | C77: L0 | D77: L0 | E77: L2 | F77: L1 | G77: L2 | H77: L1 | I77: L1 | J77: L0
A78: Security | B78: TACACS+ | C78: L1 | D78: L1 | E78: L2 | F78: L1 | G78: L2 | H78: L0 | I78: L0 | J78: L0
A79: Security | B79: RADIUS | C79: L1 | D79: L1 | E79: L2 | F79: L2 | G79: L2 | H79: L1 | I79: L1 | J79: L0
A80: Syslog & Monitoring | B80: Zabbix | C80: L1 | D80: L1 | E80: L2 | F80: L2 | G80: L2 | H80: L2 | I80: L2 | J80: L2
A81: Syslog & Monitoring | B81: Splunk | C81: L0 | D81: L0 | E81: L1 | F81: L1 | G81: L1 | H81: L1 | I81: L0 | J81: L0
A82: Syslog & Monitoring | B82: PRTG | C82: L2 | D82: L1 | E82: L1 | F82: L1 | G82: L2 | H82: L0 | I82: L0 | J82: L1
A83: Syslog & Monitoring | B83: OpManager | C83: L0 | D83: L0 | E83: L1 | F83: L1 | G83: L2 | H83: L0 | I83: L1 | J83: L0
A84: Syslog & Monitoring | B84: LOG360 | C84: L1 | D84: L0 | E84: L1 | F84: L1 | G84: L2 | H84: L0 | I84: L1 | J84: L0
... A110: Container Platform | B110: Rancher | C110: L0 | D110: L0 | E110: L0 | F110: L0 | G110: L0 | H110: L0 | I110: L0 | J110: L0
A111: *Other Skills (Just need to be able to read and understand basic code, and perform basic configuration or environment setup)
A112: Basic Database Querying | B112: SQL Server | C112: L1 | D112: L2 | E112: L2 | F112: L2 | G112: L2 | H112: L1 | I112: L1 | J112: L1
A113: Basic Database Querying | B113: PostgreSQL | C113: L1 | D113: L2 | E113: L1 | F113: L2 | G113: L2 | H113: L1 | I113: L1 | J113: L1
A114: Basic Database Querying | B114: MySQL | C114: L1 | D114: L2 | E114: L2 | F114: L2 | G114: L2 | H114: L1 | I114: L0 | J114: L1
A115: Basic Database Querying | B115: Oracle DB | C115: L0 | D115: L0 | E115: L0 | F115: L2 | G115: L0 | H115: L0 | I115: L0 | J115: L0
A116: Basic Programming | B116: Python | C116: L1 | D116: L0 | E116: L1 | F116: L2 | G116: L0 | H116: L0 | I116: L1 | J116: L2
A117: Basic Programming | B117: C# | C117: L0 | D117: L0 | E117: L1 | F117: L2 | G117: L0 | H117: L0 | I117: L0 | J117: L1
A118: Basic Programming | B118: C++ | C118: L0 | D118: L0 | E118: L1 | F118: L2 | G118: L0 | H118: L0 | I118: L1 | J118: L1
A119: Basic Programming | B119: React | C119: L0 | D119: L0 | E119: L0 | F119: L2 | G119: L0 | H119: L0 | I119: L0 | J119: L2
A120: Log file analysis and troubleshooting | B120: All systems, applications, ... | C120: L1 | D120: L1 | E120: L1 | F120: L2 | G120: L1 | H120: L1 | I120: L1 | J120: L1

Sheet Competency Definition
A1: Level | B1: Tên mức | C1: Mô tả năng lực
A2: L0 | B2: Chưa có kiến thức | C2: Chưa biết hoặc chưa từng tiếp cận kỹ năng/công nghệ này.
A3: L1 | B3: Đã biết, chưa thực hành thành công | C3: Đã có kiến thức cơ bản nhưng chưa thực hiện bài lab, hoặc đã thực hiện nhưng chưa hoàn thành thành công.
A4: L2 | B4: Đã thực hành thành công | C4: Có kiến thức và đã hoàn thành bài lab thành công; có thể thực hiện lại theo tài liệu hoặc hướng dẫn.

Sheet Skill Dashboard
A1: TEAM SKILL DASHBOARD
A2: Tổng quan năng lực theo Domain và thành viên — tự cập nhật khi bổ sung dữ liệu trong Team Skill Matrix
A4: DOMAIN | D4: SKILL | G4: THÀNH VIÊN | J4: ĐỘ PHỦ ĐÁNH GIÁ | M4: ĐIỂM TB TOÀN ĐỘI
A5: =ROWS(_xlfn.ANCHORARRAY('Chart Data'!A2)) -> 16 | D5: =SUM(_xlfn.CHOOSECOLS(_xlfn.ANCHORARRAY('Chart Data'!A2),3)) -> 118 | G5: =ROWS(_xlfn.ANCHORARRAY('Chart Data'!E2)) -> 9 | J5: =SUM(_xlfn.CHOOSECOLS(_xlfn.ANCHORARRAY('Chart Data'!E2),3))/(SUM(_xlfn.CHOOSECOLS(_xlfn.ANCHORARRAY('Chart Data'!A2),3))*ROWS(_xlfn.ANCHORARRAY('Chart Data'!E2))) -> 0.88794727 | M5: =SUMPRODUCT(_xlfn.CHOOSECOLS(_xlfn.ANCHORARRAY('Chart Data'!E2),2),_xlfn.CHOOSECOLS(_xlfn.ANCHORARRAY('Chart Data'!E2),3))/SUM(_xlfn.CHOOSECOLS(_xlfn.ANCHORARRAY('Chart Data'!E2),3)) -> 1.1198303
A8: NĂNG LỰC TRUNG BÌNH THEO DOMAIN | H8: NĂNG LỰC TRUNG BÌNH THEO THÀNH VIÊN
A32: Quy ước: L0 = 0, L1 = 1, L2 = 2. Ô trống được xem là chưa đánh giá và không tính vào điểm trung bình.
A34: PHÂN TÍCH NĂNG LỰC THEO THÀNH VIÊN
A35: Thành viên: | B35: Tuấn | E35: ="Đang xem: "&B35 -> Đang xem: Tuấn | H35: Domain: | I35: Windows Server | L35: Chuẩn Skill: | M35: 0.6
A36: TỶ LỆ NĂNG LỰC THEO DOMAIN | H36: TỶ LỆ TỪNG SKILL TRONG DOMAIN
A61: Quy đổi L0 = 0%, L1 = 50%, L2 = 100%. Radar so sánh với trung bình đội; chuẩn Skill có thể điều chỉnh tại ô M35.

Sheet Project
A1: PROJECT PORTFOLIO & DELIVERY OWNERSHIP | AA1: Thành viên | AB1: Trạng thái dự án | AC1: Trạng thái hạng mục | AD1: Loại dự án | AE1: Ưu tiên | AF1: Sức khỏe RAG | AG1: Giai đoạn
A2: Theo dõi dự án đã triển khai / sắp triển khai, thành phần kỹ thuật và trách nhiệm của từng thành viên | AA2: {=_xlfn.ANCHORARRAY('Chart Data'!M2)} -> Toàn | AB2: Chuẩn bị | AC2: Chưa bắt đầu | AD2: Mới triển khai | AE2: Cao | AF2: Xanh | AG2: Khởi động
AA3: Long | AB3: Đang triển khai | AC3: Đang thực hiện | AD3: Nâng cấp | AE3: Trung bình | AF3: Vàng | AG3: Lập kế hoạch
A4: Tổng dự án | D4: Đang triển khai | G4: Hoàn thành | J4: Đã phân công | AA4: Tuấn | AB4: Hoàn thành | AC4: Hoàn thành | AD4: Mở rộng | AE4: Thấp | AF4: Đỏ | AG4: Thực hiện
A5: =COUNTIF(A10:A29,"<>") -> 1 | D5: =COUNTIF(C10:C29,"Đang triển khai") -> 0 | G5: =COUNTIF(C10:C29,"Hoàn thành") -> 0 | J5: =COUNTIF(E34:E127,"<>") -> 0 | AA5: Duy | AB5: Tạm dừng | AC5: Bị chặn | AD5: Bảo trì | AG5: Nghiệm thu
A6: Dự án đã khai báo | D6: Cần theo dõi tiến độ | G6: Đã nghiệm thu / bàn giao | J6: Thành phần có người phụ trách | AA6: Sang | AD6: PoC | AG6: Đóng dự án
AA7: Bảo
A8: DANH MỤC DỰ ÁN | AA8: Thông
A9: Mã dự án | B9: Tên dự án | C9: Trạng thái | D9: Loại dự án | E9: Ngày bắt đầu | F9: Ngày hoàn thành KH | G9: Phụ trách dự án | H9: Thành viên tham gia | I9: Mục tiêu / Phạm vi | J9: Số thành phần | K9: Tiến độ | L9: Ghi chú | M9: Toàn | N9: Long | O9: Tuấn | P9: Sang | Q9: Bảo | R9: Thi | S9: Thông | T9: Khánh | U9: Sponsor | V9: Người giám sát | W9: Ưu tiên | X9: Sức khỏe RAG | Y9: Giai đoạn | Z9: Ngày cập nhật | AA9: Khánh
D10: Mới triển khai | J10: =IF(A10="","",COUNTIF($B$34:$B$127,A10)) -> 0 | K10: =IF(A10="","",IFERROR(COUNTIFS($B$34:$B$127,A10,$H$34:$H$127,"Hoàn thành")/COUNTIF($B$34:$B$127,A10),0)) -> 0 | AA10: NV.A
H11: {=IF(A11="","",_xlfn.TEXTJOIN(", ",TRUE,IF(M11:T11="Có",M$9:T$9,"")))} | J11: =IF(A11="","",COUNTIF($B$34:$B$127,A11)) | K11: =IF(A11="","",IFERROR(COUNTIFS($B$34:$B$127,A11,$H$34:$H$127,"Hoàn thành")/COUNTIF($B$34:$B$127,A11),0))
H12: {=IF(A12="","",_xlfn.TEXTJOIN(", ",TRUE,IF(M12:T12="Có",M$9:T$9,"")))} | J12: =IF(A12="","",COUNTIF($B$34:$B$127,A12)) | K12: =IF(A12="","",IFERROR(COUNTIFS($B$34:$B$127,A12,$H$34:$H$127,"Hoàn thành")/COUNTIF($B$34:$B$127,A12),0))
H13: {=IF(A13="","",_xlfn.TEXTJOIN(", ",TRUE,IF(M13:T13="Có",M$9:T$9,"")))} | J13: =IF(A13="","",COUNTIF($B$34:$B$127,A13)) | K13: =IF(A13="","",IFERROR(COUNTIFS($B$34:$B$127,A13,$H$34:$H$127,"Hoàn thành")/COUNTIF($B$34:$B$127,A13),0))
H14: {=IF(A14="","",_xlfn.TEXTJOIN(", ",TRUE,IF(M14:T14="Có",M$9:T$9,"")))} | J14: =IF(A14="","",COUNTIF($B$34:$B$127,A14)) | K14: =IF(A14="","",IFERROR(COUNTIFS($B$34:$B$127,A14,$H$34:$H$127,"Hoàn thành")/COUNTIF($B$34:$B$127,A14),0))
H15: {=IF(A15="","",_xlfn.TEXTJOIN(", ",TRUE,IF(M15:T15="Có",M$9:T$9,"")))} | J15: =IF(A15="","",COUNTIF($B$34:$B$127,A15)) | K15: =IF(A15="","",IFERROR(COUNTIFS($B$34:$B$127,A15,$H$34:$H$127,"Hoàn thành")/COUNTIF($B$34:$B$127,A15),0))
H16: {=IF(A16="","",_xlfn.TEXTJOIN(", ",TRUE,IF(M16:T16="Có",M$9:T$9,"")))} | J16: =IF(A16="","",COUNTIF($B$34:$B$127,A16)) | K16: =IF(A16="","",IFERROR(COUNTIFS($B$34:$B$127,A16,$H$34:$H$127,"Hoàn thành")/COUNTIF($B$34:$B$127,A16),0))
H17: {=IF(A17="","",_xlfn.TEXTJOIN(", ",TRUE,IF(M17:T17="Có",M$9:T$9,"")))} | J17: =IF(A17="","",COUNTIF($B$34:$B$127,A17)) | K17: =IF(A17="","",IFERROR(COUNTIFS($B$34:$B$127,A17,$H$34:$H$127,"Hoàn thành")/COUNTIF($B$34:$B$127,A17),0))
H18: {=IF(A18="","",_xlfn.TEXTJOIN(", ",TRUE,IF(M18:T18="Có",M$9:T$9,"")))} | J18: =IF(A18="","",COUNTIF($B$34:$B$127,A18)) | K18: =IF(A18="","",IFERROR(COUNTIFS($B$34:$B$127,A18,$H$34:$H$127,"Hoàn thành")/COUNTIF($B$34:$B$127,A18),0))
H19: {=IF(A19="","",_xlfn.TEXTJOIN(", ",TRUE,IF(M19:T19="Có",M$9:T$9,"")))} | J19: =IF(A19="","",COUNTIF($B$34:$B$127,A19)) | K19: =IF(A19="","",IFERROR(COUNTIFS($B$34:$B$127,A19,$H$34:$H$127,"Hoàn thành")/COUNTIF($B$34:$B$127,A19),0))
H20: {=IF(A20="","",_xlfn.TEXTJOIN(", ",TRUE,IF(M20:T20="Có",M$9:T$9,"")))} | J20: =IF(A20="","",COUNTIF($B$34:$B$127,A20)) | K20: =IF(A20="","",IFERROR(COUNTIFS($B$34:$B$127,A20,$H$34:$H$127,"Hoàn thành")/COUNTIF($B$34:$B$127,A20),0))
H21: {=IF(A21="","",_xlfn.TEXTJOIN(", ",TRUE,IF(M21:T21="Có",M$9:T$9,"")))} | J21: =IF(A21="","",COUNTIF($B$34:$B$127,A21)) | K21: =IF(A21="","",IFERROR(COUNTIFS($B$34:$B$127,A21,$H$34:$H$127,"Hoàn thành")/COUNTIF($B$34:$B$127,A21),0))
H22: {=IF(A22="","",_xlfn.TEXTJOIN(", ",TRUE,IF(M22:T22="Có",M$9:T$9,"")))} | J22: =IF(A22="","",COUNTIF($B$34:$B$127,A22)) | K22: =IF(A22="","",IFERROR(COUNTIFS($B$34:$B$127,A22,$H$34:$H$127,"Hoàn thành")/COUNTIF($B$34:$B$127,A22),0))
... H29: {=IF(A29="","",_xlfn.TEXTJOIN(", ",TRUE,IF(M29:T29="Có",M$9:T$9,"")))} | J29: =IF(A29="","",COUNTIF($B$34:$B$127,A29)) | K29: =IF(A29="","",IFERROR(COUNTIFS($B$34:$B$127,A29,$H$34:$H$127,"Hoàn thành")/COUNTIF($B$34:$B$127,A29),0))
A30: Cách chọn nhiều người: tại các cột tên thành viên, chọn “Có”; cột Thành viên tham gia sẽ tự động tổng hợp danh sách.
A32: THÀNH PHẦN TRIỂN KHAI & PHÂN CÔNG
A33: Mã hạng mục | B33: Mã dự án | C33: Domain | D33: Skill / Thành phần | E33: Phụ trách hạng mục | F33: Người tham gia | G33: Vai trò / Trách nhiệm | H33: Trạng thái | I33: Ngày bắt đầu | J33: Ngày hoàn thành | K33: Kết quả / Bằng chứng | L33: Ghi chú
A34: CMP-001 | C34: Virtualization | D34: VMware ESXi | H34: Chưa bắt đầu
A35: CMP-002 | C35: Virtualization | D35: VMware vCenter | H35: Chưa bắt đầu
A36: CMP-003 | C36: Virtualization | D36: VMware vSAN | H36: Chưa bắt đầu
A37: CMP-004 | C37: Virtualization | D37: VMware NSX | H37: Chưa bắt đầu
A38: CMP-005 | C38: Virtualization | D38: VMware Horizon | H38: Chưa bắt đầu
A39: CMP-006 | C39: Virtualization | D39: Proxmox VE | H39: Chưa bắt đầu
A40: CMP-007 | C40: Virtualization | D40: Hyper-V | H40: Chưa bắt đầu
A41: CMP-008 | C41: Virtualization | D41: VergeIO | H41: Chưa bắt đầu
A42: CMP-009 | C42: Virtualization | D42: Nutanix | H42: Chưa bắt đầu
A43: CMP-010 | C43: Virtualization | D43: CloudStack | H43: Chưa bắt đầu
A44: CMP-011 | C44: Container Platform | D44: Docker | H44: Chưa bắt đầu
A45: CMP-012 | C45: Container Platform | D45: Kubernetes | H45: Chưa bắt đầu
... A127: CMP-094 | C127: AI Infrastructure | D127: RAG Architecture | H127: Chưa bắt đầu

Sheet Project Control
A1: PROJECT CONTROL CENTER | N1: Thành viên | O1: Milestone | P1: Loại R/I | Q1: Mức | R1: Trạng thái R/I | S1: Loại D/C | T1: Trạng thái D/C | U1: Nghiệm thu | V1: Có/Không
A2: Theo dõi mốc tiến độ, rủi ro, quyết định thay đổi và nghiệm thu theo từng dự án | N2: {=_xlfn.ANCHORARRAY('Chart Data'!M2)} -> Toàn | O2: Chưa bắt đầu | P2: Rủi ro | Q2: Thấp | R2: Mở | S2: Quyết định | T2: Chờ duyệt | U2: Chưa sẵn sàng | V2: Có
N3: Long | O3: Đang thực hiện | P3: Vấn đề | Q3: Trung bình | R3: Đang xử lý | S3: Yêu cầu thay đổi | T3: Đã duyệt | U3: Chờ nghiệm thu | V3: Không
A4: Mốc quá hạn | D4: Rủi ro / vấn đề mở | G4: Thay đổi chờ duyệt | J4: Chờ nghiệm thu | N4: Tuấn | O4: Hoàn thành | Q4: Cao | R4: Đã đóng | T4: Từ chối | U4: Đạt
A5: =COUNTIFS($E$9:$E$28,"<"&TODAY(),$G$9:$G$28,"<>Hoàn thành",$B$9:$B$28,"<>") -> 0 | D5: =COUNTIF($J$33:$J$52,"Mở")+COUNTIF($J$33:$J$52,"Đang xử lý") -> 0 | G5: =COUNTIF($H$57:$H$76,"Chờ duyệt") -> 0 | J5: =COUNTIF($H$81:$H$100,"Chờ nghiệm thu") -> 0 | N5: Duy | O5: Trễ | T5: Đã triển khai | U5: Không đạt
A6: Cần xử lý tiến độ | D6: Chưa đóng hoàn toàn | G6: Cần quyết định | J6: Cần xác nhận kết quả | N6: Sang
A7: MILESTONE & TIẾN ĐỘ | N7: Bảo
A8: Mã mốc | B8: Mã dự án | C8: Mốc / Kết quả | D8: Owner | E8: Hạn KH | F8: Ngày hoàn thành | G8: Trạng thái | H8: % hoàn thành | I8: Phụ thuộc | J8: Ghi chú | N8: Thông
A9: =IF(B9="","","MS-"&TEXT(ROW()-8,"000")) | N9: Khánh
A10: =IF(B10="","","MS-"&TEXT(ROW()-8,"000")) | N10: NV.A
A11: =IF(B11="","","MS-"&TEXT(ROW()-8,"000"))
A12: =IF(B12="","","MS-"&TEXT(ROW()-8,"000"))
A13: =IF(B13="","","MS-"&TEXT(ROW()-8,"000"))
A14: =IF(B14="","","MS-"&TEXT(ROW()-8,"000"))
A15: =IF(B15="","","MS-"&TEXT(ROW()-8,"000"))
A16: =IF(B16="","","MS-"&TEXT(ROW()-8,"000"))
A17: =IF(B17="","","MS-"&TEXT(ROW()-8,"000"))
A18: =IF(B18="","","MS-"&TEXT(ROW()-8,"000"))
A19: =IF(B19="","","MS-"&TEXT(ROW()-8,"000"))
A20: =IF(B20="","","MS-"&TEXT(ROW()-8,"000"))
A21: =IF(B21="","","MS-"&TEXT(ROW()-8,"000"))
A22: =IF(B22="","","MS-"&TEXT(ROW()-8,"000"))
... A28: =IF(B28="","","MS-"&TEXT(ROW()-8,"000"))
A31: RỦI RO & VẤN ĐỀ
A32: Mã R/I | B32: Mã dự án | C32: Loại | D32: Mô tả | E32: Xác suất | F32: Tác động | G32: Mức độ | H32: Owner | I32: Hạn xử lý | J32: Trạng thái | K32: Biện pháp xử lý | L32: Cập nhật gần nhất
A33: =IF(B33="","","RI-"&TEXT(ROW()-32,"000")) | G33: =IF(OR(E33="",F33=""),"",IF(MATCH(E33,{"Thấp","Trung bình","Cao"},0)*MATCH(F33,{"Thấp","Trung bình","Cao"},0)>=6,"Cao",IF(MATCH(E33,{"Thấp","Trung bình","Cao"},0)*MATCH(F33,{"Thấp","Trung bình","Cao"},0)>=3,"Trung bình","Thấp")))
A34: =IF(B34="","","RI-"&TEXT(ROW()-32,"000")) | G34: =IF(OR(E34="",F34=""),"",IF(MATCH(E34,{"Thấp","Trung bình","Cao"},0)*MATCH(F34,{"Thấp","Trung bình","Cao"},0)>=6,"Cao",IF(MATCH(E34,{"Thấp","Trung bình","Cao"},0)*MATCH(F34,{"Thấp","Trung bình","Cao"},0)>=3,"Trung bình","Thấp")))
A35: =IF(B35="","","RI-"&TEXT(ROW()-32,"000")) | G35: =IF(OR(E35="",F35=""),"",IF(MATCH(E35,{"Thấp","Trung bình","Cao"},0)*MATCH(F35,{"Thấp","Trung bình","Cao"},0)>=6,"Cao",IF(MATCH(E35,{"Thấp","Trung bình","Cao"},0)*MATCH(F35,{"Thấp","Trung bình","Cao"},0)>=3,"Trung bình","Thấp")))
A36: =IF(B36="","","RI-"&TEXT(ROW()-32,"000")) | G36: =IF(OR(E36="",F36=""),"",IF(MATCH(E36,{"Thấp","Trung bình","Cao"},0)*MATCH(F36,{"Thấp","Trung bình","Cao"},0)>=6,"Cao",IF(MATCH(E36,{"Thấp","Trung bình","Cao"},0)*MATCH(F36,{"Thấp","Trung bình","Cao"},0)>=3,"Trung bình","Thấp")))
A37: =IF(B37="","","RI-"&TEXT(ROW()-32,"000")) | G37: =IF(OR(E37="",F37=""),"",IF(MATCH(E37,{"Thấp","Trung bình","Cao"},0)*MATCH(F37,{"Thấp","Trung bình","Cao"},0)>=6,"Cao",IF(MATCH(E37,{"Thấp","Trung bình","Cao"},0)*MATCH(F37,{"Thấp","Trung bình","Cao"},0)>=3,"Trung bình","Thấp")))
A38: =IF(B38="","","RI-"&TEXT(ROW()-32,"000")) | G38: =IF(OR(E38="",F38=""),"",IF(MATCH(E38,{"Thấp","Trung bình","Cao"},0)*MATCH(F38,{"Thấp","Trung bình","Cao"},0)>=6,"Cao",IF(MATCH(E38,{"Thấp","Trung bình","Cao"},0)*MATCH(F38,{"Thấp","Trung bình","Cao"},0)>=3,"Trung bình","Thấp")))
A39: =IF(B39="","","RI-"&TEXT(ROW()-32,"000")) | G39: =IF(OR(E39="",F39=""),"",IF(MATCH(E39,{"Thấp","Trung bình","Cao"},0)*MATCH(F39,{"Thấp","Trung bình","Cao"},0)>=6,"Cao",IF(MATCH(E39,{"Thấp","Trung bình","Cao"},0)*MATCH(F39,{"Thấp","Trung bình","Cao"},0)>=3,"Trung bình","Thấp")))
A40: =IF(B40="","","RI-"&TEXT(ROW()-32,"000")) | G40: =IF(OR(E40="",F40=""),"",IF(MATCH(E40,{"Thấp","Trung bình","Cao"},0)*MATCH(F40,{"Thấp","Trung bình","Cao"},0)>=6,"Cao",IF(MATCH(E40,{"Thấp","Trung bình","Cao"},0)*MATCH(F40,{"Thấp","Trung bình","Cao"},0)>=3,"Trung bình","Thấp")))
A41: =IF(B41="","","RI-"&TEXT(ROW()-32,"000")) | G41: =IF(OR(E41="",F41=""),"",IF(MATCH(E41,{"Thấp","Trung bình","Cao"},0)*MATCH(F41,{"Thấp","Trung bình","Cao"},0)>=6,"Cao",IF(MATCH(E41,{"Thấp","Trung bình","Cao"},0)*MATCH(F41,{"Thấp","Trung bình","Cao"},0)>=3,"Trung bình","Thấp")))
A42: =IF(B42="","","RI-"&TEXT(ROW()-32,"000")) | G42: =IF(OR(E42="",F42=""),"",IF(MATCH(E42,{"Thấp","Trung bình","Cao"},0)*MATCH(F42,{"Thấp","Trung bình","Cao"},0)>=6,"Cao",IF(MATCH(E42,{"Thấp","Trung bình","Cao"},0)*MATCH(F42,{"Thấp","Trung bình","Cao"},0)>=3,"Trung bình","Thấp")))
A43: =IF(B43="","","RI-"&TEXT(ROW()-32,"000")) | G43: =IF(OR(E43="",F43=""),"",IF(MATCH(E43,{"Thấp","Trung bình","Cao"},0)*MATCH(F43,{"Thấp","Trung bình","Cao"},0)>=6,"Cao",IF(MATCH(E43,{"Thấp","Trung bình","Cao"},0)*MATCH(F43,{"Thấp","Trung bình","Cao"},0)>=3,"Trung bình","Thấp")))
A44: =IF(B44="","","RI-"&TEXT(ROW()-32,"000")) | G44: =IF(OR(E44="",F44=""),"",IF(MATCH(E44,{"Thấp","Trung bình","Cao"},0)*MATCH(F44,{"Thấp","Trung bình","Cao"},0)>=6,"Cao",IF(MATCH(E44,{"Thấp","Trung bình","Cao"},0)*MATCH(F44,{"Thấp","Trung bình","Cao"},0)>=3,"Trung bình","Thấp")))
... A52: =IF(B52="","","RI-"&TEXT(ROW()-32,"000")) | G52: =IF(OR(E52="",F52=""),"",IF(MATCH(E52,{"Thấp","Trung bình","Cao"},0)*MATCH(F52,{"Thấp","Trung bình","Cao"},0)>=6,"Cao",IF(MATCH(E52,{"Thấp","Trung bình","Cao"},0)*MATCH(F52,{"Thấp","Trung bình","Cao"},0)>=3,"Trung bình","Thấp")))
A55: QUYẾT ĐỊNH & YÊU CẦU THAY ĐỔI
A56: Mã D/C | B56: Mã dự án | C56: Loại | D56: Nội dung | E56: Người đề xuất | F56: Ngày đề xuất | G56: Người phê duyệt | H56: Trạng thái | I56: Ngày quyết định | J56: Ảnh hưởng phạm vi/tiến độ | K56: Hành động tiếp theo | L56: Ghi chú
...

Sheet Chart Data
A1: Domain | B1: Điểm TB | C1: Số Skill | E1: Thành viên | F1: Điểm TB | G1: Đã đánh giá | H1: Độ phủ | J1: Domain | K1: ='Skill Dashboard'!B35 -> Tuấn | L1: Trung bình đội | M1: Danh sách thành viên | O1: Skill | P1: ='Skill Dashboard'!B35 -> Tuấn | R1: Skill hiển thị | S1: ='Skill Dashboard'!B35 -> Tuấn | T1: ="Chuẩn "&TEXT('Skill Dashboard'!$M$35,"0%") -> Chuẩn 60%
A2: {=_xlfn.LET(_xlpm.d,TRIM('Team Skill'!$A$2:$A$1000),_xlpm.sk,'Team Skill'!$B$2:$B$1000,_xlpm.n,_xlfn.XMATCH("Owner",'Team Skill'!$1:$1)-3,_xlpm.x,_xlfn.TAKE('Team Skill'!$C$2:$AZ$1000,,_xlpm.n),_xlpm.u,_xlfn.UNIQUE(_xlfn._xlws.FILTER(_xlpm.d,(_xlpm.d<>"")*(_xlpm.sk<>""))),_xlpm.a,_xlfn.MAP(_xlpm.u,_xlfn.LAMBDA(_xlpm.q,IFERROR(AVERAGE(IFERROR(--RIGHT(_xlfn.TOCOL(_xlfn._xlws.FILTER(_xlpm.x,(_xlpm.d=_xlpm.q)*(_xlpm.sk<>""))),1),"")),""))),_xlpm.c,_xlfn.MAP(_xlpm.u,_xlfn.LAMBDA(_xlpm.q,SUM(--(_xlpm.d=_xlpm.q)*--(_xlpm.sk<>"")))),_xlfn.SORTBY(_xlfn.HSTACK(_xlpm.u,_xlpm.a,_xlpm.c),_xlpm.a,-1))} -> Server Basic | B2: 2 | C2: 3 | E2: {=_xlfn.LET(_xlpm.n,_xlfn.XMATCH("Owner",'Team Skill'!$1:$1)-3,_xlpm.h,_xlfn.TAKE('Team Skill'!$C$1:$AZ$1,,_xlpm.n),_xlpm.x,_xlfn.TAKE('Team Skill'!$C$2:$AZ$1000,,_xlpm.n),_xlpm.d,'Team Skill'!$A$2:$A$1000,_xlpm.sk,'Team Skill'!$B$2:$B$1000,_xlpm.v,(_xlpm.d<>"")*(_xlpm.sk<>""),_xlpm.z,_xlfn._xlws.FILTER(_xlpm.x,_xlpm.v),_xlpm.a,_xlfn.BYCOL(_xlpm.z,_xlfn.LAMBDA(_xlpm.q,IFERROR(AVERAGE(IFERROR(--RIGHT(_xlpm.q,1),"")),0))),_xlpm.c,_xlfn.BYCOL(_xlpm.z,_xlfn.LAMBDA(_xlpm.q,SUM(--(_xlpm.q<>"")))),_xlfn.SORTBY(TRANSPOSE(_xlfn.VSTACK(_xlpm.h,_xlpm.a,_xlpm.c,_xlpm.c/SUM(--_xlpm.v))),TRANSPOSE(_xlpm.a),-1))} -> Sang | F2: 1.6016949 | G2: 118 | H2: 1 | J2: {=_xlfn.LET(_xlpm.sel,'Skill Dashboard'!$B$35,_xlpm.d,TRIM('Team Skill'!$A$2:$A$1000),_xlpm.sk,'Team Skill'!$B$2:$B$1000,_xlpm.n,_xlfn.XMATCH("Owner",'Team Skill'!$1:$1)-3,_xlpm.h,_xlfn.TAKE('Team Skill'!$C$1:$AZ$1,,_xlpm.n),_xlpm.x,_xlfn.TAKE('Team Skill'!$C$2:$AZ$1000,,_xlpm.n),_xlpm.v,_xlfn.CHOOSECOLS(_xlpm.x,_xlfn.XMATCH(_xlpm.sel,_xlpm.h)),_xlpm.u,_xlfn.UNIQUE(_xlfn._xlws.FILTER(_xlpm.d,(_xlpm.d<>"")*(_xlpm.sk<>""))),_xlpm.a,_xlfn.MAP(_xlpm.u,_xlfn.LAMBDA(_xlpm.q,IFERROR(AVERAGE(IFERROR(--RIGHT(_xlfn._xlws.FILTER(_xlpm.v,(_xlpm.d=_xlpm.q)*(_xlpm.sk<>"")),1),""))/2,0))),_xlfn._xlws.SORT(_xlfn.HSTACK(_xlpm.u,_xlpm.a),1,1))} -> Basic Database Querying | K2: 0.625 | L2: {=_xlfn.LET(_xlpm.u,_xlfn.CHOOSECOLS(_xlfn.ANCHORARRAY(J2),1),_xlfn.XLOOKUP(_xlpm.u,_xlfn.CHOOSECOLS(_xlfn.ANCHORARRAY(A2),1),_xlfn.CHOOSECOLS(_xlfn.ANCHORARRAY(A2),2),0)/2)} -> 0.5625 | M2: {=_xlfn.LET(_xlpm.n,_xlfn.XMATCH("Owner",'Team Skill'!$1:$1)-3,TRANSPOSE(_xlfn.TAKE('Team Skill'!$C$1:$AZ$1,,_xlpm.n)))} -> Toàn | O2: {=_xlfn.LET(_xlpm.sel,'Skill Dashboard'!$B$35,_xlpm.dom,'Skill Dashboard'!$I$35,_xlpm.d,TRIM('Team Skill'!$A$2:$A$1000),_xlpm.sk,'Team Skill'!$B$2:$B$1000,_xlpm.n,_xlfn.XMATCH("Owner",'Team Skill'!$1:$1)-3,_xlpm.h,_xlfn.TAKE('Team Skill'!$C$1:$AZ$1,,_xlpm.n),_xlpm.x,_xlfn.TAKE('Team Skill'!$C$2:$AZ$1000,,_xlpm.n),_xlpm.v,_xlfn.CHOOSECOLS(_xlpm.x,_xlfn.XMATCH(_xlpm.sel,_xlpm.h)),_xlfn._xlws.FILTER(_xlfn.HSTACK(_xlpm.sk,IF(_xlpm.v="","",IFERROR(--RIGHT(_xlpm.v,1)/2,""))),(_xlpm.d=TRIM(_xlpm.dom))*(_xlpm.sk<>"")))} -> Windows Server Administration | P2: 1 | R2: {=IFERROR(INDEX(_xlfn.CHOOSECOLS(_xlfn.ANCHORARRAY($O$2),1),ROWS($R$2:R2)),"")} -> Windows Server Administration | S2: {=IFERROR(INDEX(_xlfn.CHOOSECOLS(_xlfn.ANCHORARRAY($O$2),2),ROWS($S$2:S2)),"")} -> 1 | T2: =IF(R2<>"",'Skill Dashboard'!$M$35,"") -> 0.6
A3: Windows Server | B3: 1.7638889 | C3: 9 | E3: Duy | F3: 1.4957265 | G3: 117 | H3: 0.99152542 | J3: Basic Programming | K3: 0.375 | L3: 0.3125 | M3: Long | O3: Active Directory Domain Services (AD DS) | P3: 1 | R3: {=IFERROR(INDEX(_xlfn.CHOOSECOLS(_xlfn.ANCHORARRAY($O$2),1),ROWS($R$2:R3)),"")} -> Active Directory Domain Services (AD DS) | S3: {=IFERROR(INDEX(_xlfn.CHOOSECOLS(_xlfn.ANCHORARRAY($O$2),2),ROWS($S$2:S3)),"")} -> 1 | T3: =IF(R3<>"",'Skill Dashboard'!$M$35,"") -> 0.6
A4: Network | B4: 1.40625 | C4: 8 | E4: Tuấn | F4: 1.4237288 | G4: 118 | H4: 1 | J4: Container Platform | K4: 0.375 | L4: 0.25 | M4: Tuấn | O4: Group Policy (GPO) | P4: 1 | R4: {=IFERROR(INDEX(_xlfn.CHOOSECOLS(_xlfn.ANCHORARRAY($O$2),1),ROWS($R$2:R4)),"")} -> Group Policy (GPO) | S4: {=IFERROR(INDEX(_xlfn.CHOOSECOLS(_xlfn.ANCHORARRAY($O$2),2),ROWS($S$2:S4)),"")} -> 1 | T4: =IF(R4<>"",'Skill Dashboard'!$M$35,"") -> 0.6
A5: Linux Server | B5: 1.35 | C5: 10 | E5: Long | F5: 1.0169492 | G5: 118 | H5: 1 | J5: Database (Deploy & Basic configuration) | K5: 0.75 | L5: 0.609375 | M5: Duy | O5: Active Directory Certificate Services (AD CS) | P5: 1 | R5: {=IFERROR(INDEX(_xlfn.CHOOSECOLS(_xlfn.ANCHORARRAY($O$2),1),ROWS($R$2:R5)),"")} -> Active Directory Certificate Services (AD CS) | S5: {=IFERROR(INDEX(_xlfn.CHOOSECOLS(_xlfn.ANCHORARRAY($O$2),2),ROWS($S$2:S5)),"")} -> 1 | T5: =IF(R5<>"",'Skill Dashboard'!$M$35,"") -> 0.6
A6: Database (Deploy & Basic configuration) | B6: 1.21875 | C6: 4 | E6: Toàn | F6: 0.99152542 | G6: 118 | H6: 1 | J6: Firewall | K6: 0.75 | L6: 0.53125 | M6: Sang | O6: DNS | P6: 1 | R6: {=IFERROR(INDEX(_xlfn.CHOOSECOLS(_xlfn.ANCHORARRAY($O$2),1),ROWS($R$2:R6)),"")} -> DNS | S6: {=IFERROR(INDEX(_xlfn.CHOOSECOLS(_xlfn.ANCHORARRAY($O$2),2),ROWS($S$2:S6)),"")} -> 1 | T6: =IF(R6<>"",'Skill Dashboard'!$M$35,"") -> 0.6
A7: Wireless | B7: 1.2083333 | C7: 6 | E7: Bảo | F7: 0.95762712 | G7: 118 | H7: 1 | J7: Linux Server | K7: 0.8 | L7: 0.675 | M7: Bảo | O7: DHCP | P7: 1 | R7: {=IFERROR(INDEX(_xlfn.CHOOSECOLS(_xlfn.ANCHORARRAY($O$2),1),ROWS($R$2:R7)),"")} -> DHCP | S7: {=IFERROR(INDEX(_xlfn.CHOOSECOLS(_xlfn.ANCHORARRAY($O$2),2),ROWS($S$2:S7)),"")} -> 1 | T7: =IF(R7<>"",'Skill Dashboard'!$M$35,"") -> 0.6
A8: Basic Database Querying | B8: 1.125 | C8: 4 | E8: Khánh | F8: 0.74576271 | G8: 118 | H8: 1 | J8: Log file analysis and troubleshooting | K8: 0.5 | L8: 0.5625 | M8: Thông | O8: IIS | P8: 1 | R8: {=IFERROR(INDEX(_xlfn.CHOOSECOLS(_xlfn.ANCHORARRAY($O$2),1),ROWS($R$2:R8)),"")} -> IIS | S8: {=IFERROR(INDEX(_xlfn.CHOOSECOLS(_xlfn.ANCHORARRAY($O$2),2),ROWS($S$2:S8)),"")} -> 1 | T8: =IF(R8<>"",'Skill Dashboard'!$M$35,"") -> 0.6
A9: Log file analysis and troubleshooting | B9: 1.125 | C9: 1 | E9: Thông | F9: 0.72881356 | G9: 118 | H9: 1 | J9: Network | K9: 0.8125 | L9: 0.703125 | M9: Khánh | O9: Failover Clustering | P9: 1 | R9: {=IFERROR(INDEX(_xlfn.CHOOSECOLS(_xlfn.ANCHORARRAY($O$2),1),ROWS($R$2:R9)),"")} -> Failover Clustering | S9: {=IFERROR(INDEX(_xlfn.CHOOSECOLS(_xlfn.ANCHORARRAY($O$2),2),ROWS($S$2:S9)),"")} -> 1 | T9: =IF(R9<>"",'Skill Dashboard'!$M$35,"") -> 0.6
A10: Firewall | B10: 1.0625 | C10: 8 | E10: NV.A | F10: 0 | G10: 0 | H10: 0 | J10: Security | K10: 0.8 | L10: 0.46835443 | M10: NV.A | O10: File Services | P10: 1 | R10: {=IFERROR(INDEX(_xlfn.CHOOSECOLS(_xlfn.ANCHORARRAY($O$2),1),ROWS($R$2:R10)),"")} -> File Services | S10: {=IFERROR(INDEX(_xlfn.CHOOSECOLS(_xlfn.ANCHORARRAY($O$2),2),ROWS($S$2:S10)),"")} -> 1 | T10: =IF(R10<>"",'Skill Dashboard'!$M$35,"") -> 0.6
A11: Storage & Backup | B11: 1.0104167 | C11: 12 | J11: Server Basic | K11: 1 | L11: 1 | R11: {=IFERROR(INDEX(_xlfn.CHOOSECOLS(_xlfn.ANCHORARRAY($O$2),1),ROWS($R$2:R11)),"")} | S11: {=IFERROR(INDEX(_xlfn.CHOOSECOLS(_xlfn.ANCHORARRAY($O$2),2),ROWS($S$2:S11)),"")} | T11: =IF(R11<>"",'Skill Dashboard'!$M$35,"")
A12: Virtualization | B12: 0.97916667 | C12: 12 | J12: Storage & Backup | K12: 0.70833333 | L12: 0.50520833 | R12: {=IFERROR(INDEX(_xlfn.CHOOSECOLS(_xlfn.ANCHORARRAY($O$2),1),ROWS($R$2:R12)),"")} | S12: {=IFERROR(INDEX(_xlfn.CHOOSECOLS(_xlfn.ANCHORARRAY($O$2),2),ROWS($S$2:S12)),"")} | T12: =IF(R12<>"",'Skill Dashboard'!$M$35,"")
A13: UC & Contact Center | B13: 0.95833333 | C13: 12 | J13: Syslog & Monitoring | K13: 0.59090909 | L13: 0.45454545 | R13: {=IFERROR(INDEX(_xlfn.CHOOSECOLS(_xlfn.ANCHORARRAY($O$2),1),ROWS($R$2:R13)),"")} | S13: {=IFERROR(INDEX(_xlfn.CHOOSECOLS(_xlfn.ANCHORARRAY($O$2),2),ROWS($S$2:S13)),"")} | T13: =IF(R13<>"",'Skill Dashboard'!$M$35,"")
A14: Security | B14: 0.93670886 | C14: 10 | J14: UC & Contact Center | K14: 0.70833333 | L14: 0.47916667
A15: Syslog & Monitoring | B15: 0.90909091 | C15: 11 | J15: Virtualization | K15: 0.5 | L15: 0.48958333
A16: Basic Programming | B16: 0.625 | C16: 4 | J16: Windows Server | K16: 1 | L16: 0.88194444
A17: Container Platform | B17: 0.5 | C17: 4 | J17: Wireless | K17: 0.83333333 | L17: 0.60416667
